Workbook

Sheet Instructions_说明
A1: 作答说明（为了贴合大五人格量表的本意）：
A2: 1) 请根据你在“过去6–12个月里大多数时候”的真实状态作答，而不是最近某一天/某个特殊情境。
A3: 2) 1–5分：1=非常不同意，2=不同意，3=一般/不确定，4=同意，5=非常同意。
A4: 3) 没有对错；请尽量直觉作答，不要反复纠结。
A5: 4) 计分会自动处理反向题；你只需要在 Test_Sorted 页的“作答(1-5)”列填写即可。
A6: 5) “Facet_Def/分面定义、Reverse_Warn/反向提醒、Item_Anchor/题目锚点”三列用于帮助理解题意：分面背景、反向逻辑提醒、题目情境锚点；仅作理解参考，不参与计分。

Sheet Sheet 1
A1: Number | B1: Sign | C1: Key&Num. | D1: Item | E1: Chinese Translated Item with Subject.
A2: 4 | B2: + | C2: A1_01 | D2: Trust others. | E2: 我信任他人。
A3: 34 | B3: + | C3: A1_02 | D3: Believe that others have good intentions. | E3: 我相信他人是心怀好意的。
A4: 64 | B4: + | C4: A1_03 | D4: Trust what people say. | E4: 我信任别人说的话。
A5: 94 | B5: + | C5: A1_04 | D5: Believe that people are basically moral. | E5: 我相信人从根本上来说都是遵守道德的。
A6: 124 | B6: + | C6: A1_05 | D6: Believe in human goodness. | E6: 我相信人类是善良的。
A7: 154 | B7: + | C7: A1_06 | D7: Think that all will be well. | E7: 我认为一切事情都会变好。
A8: 184 | B8: _ | C8: A1_07 | D8: Distrust people. | E8: 我不信任他人。
A9: 214 | B9: _ | C9: A1_08 | D9: Suspect hidden motives in others. | E9: 我怀疑他人另有所谋。
A10: 244 | B10: _ | C10: A1_09 | D10: Am wary of others. | E10: 我对他人心存戒备。
A11: 274 | B11: _ | C11: A1_10 | D11: Believe that people are essentially evil. | E11: 我相信人本质上是邪恶的。
A12: 9 | B12: + | C12: A2_01 | D12: Would never cheat on my taxes. | E12: 我永远不会作弊。
A13: 39 | B13: + | C13: A2_02 | D13: Stick to the rules. | E13: 我谨守规则。
... A301: 298 | B301: _ | C301: O6_10 | D301: Like to stand during the national anthem. | E301: 我喜欢在唱国歌时起立。

Sheet Test_Sorted
A1: Number | B1: Sign | C1: Key&Num. | D1: Item | E1: Chinese Translated Item with Subject. | F1: Response (1-5) / 作答(1-5) | G1: Item_Anchor（题目锚点） | H1: Scored / 计分 | I1: Facet_Def（分面定义） | J1: Reverse_Warn（反向提醒） | K1: Facet / 分面(隐藏)
A2: 1 | B2: + | C2: N1_01 | D2: Worry about things. | E2: 我总是对事情感到担忧。 | F2: 4.5 | G2: • 容易把小问题往坏处想、反复琢磨（如消息未回、任务细节） • 在等待结果或不确定时更难放松（如考试/面试/体检） | H2: =IF(ISBLANK(F2),"",IF($B2="+",F2,6-F2)) -> 4.5 | I2: [N1] 焦虑｜神经质（Neuroticism） 定义：对潜在威胁与不确定性更敏感，容易担心与紧张 关注：社交评价担忧；健康/安全担忧；未来不确定性担忧 | K2: =LEFT($C2,FIND("_",$C2)-1) -> N1
A3: 2 | B3: + | C3: E1_01 | D3: Make friends easily. | E3: 我很容易交到朋友。 | F3: 3 | G3: • 看的是人际温暖与亲近感，而非社交技巧高低 • 关键词提示：make / friends / easily | H3: =IF(ISBLANK(F3),"",IF($B3="+",F3,6-F3)) -> 3 | I3: [E1] 友善/热情｜外向性（Extraversion） 定义：更温暖、亲近他人，容易主动交流 关注：主动搭话；表达关心；氛围友好 | K3: =LEFT($C3,FIND("_",$C3)-1) -> E1
A4: 3 | B4: + | C4: O1_01 | D4: Have a vivid imagination. | E4: 我有丰富的想像力。 | F4: 4 | G4: • 经常沉浸在联想/幻想/脑内情境（如构思故事、假设情景） • 更容易把普通事物想出新画面或可能性 | H4: =IF(ISBLANK(F4),"",IF($B4="+",F4,6-F4)) -> 4 | I4: [O1] 想象力｜开放性（Openness） 定义：内心画面与联想更丰富，常沉浸思考/幻想 关注：白日梦；创意联想；构建情境 | K4: =LEFT($C4,FIND("_",$C4)-1) -> O1
A5: 4 | B5: + | C5: A1_01 | D5: Trust others. | E5: 我信任他人。 | F5: 2 | G5: • 更倾向相信别人是诚恳的（不轻易怀疑动机） • 在信息不全时更愿意给对方“好意解释” | H5: =IF(ISBLANK(F5),"",IF($B5="+",F5,6-F5)) -> 2 | I5: [A1] 信任｜宜人性（Agreeableness） 定义：更倾向相信他人动机良善，不易猜疑 关注：默认善意；少怀疑；愿意托付 | K5: =LEFT($C5,FIND("_",$C5)-1) -> A1
A6: 5 | B6: + | C6: C1_01 | D6: Complete tasks successfully. | E6: 我总是成功的完成任务。 | F6: 4 | G6: • 看的是胜任感与解决问题的自信，而非自负 • 关键词提示：complete / tasks / successfully | H6: =IF(ISBLANK(F6),"",IF($B6="+",F6,6-F6)) -> 4 | I6: [C1] 自我效能｜尽责性（Conscientiousness） 定义：更自信能把事情做好，感到胜任 关注：能搞定问题；学习快；靠谱 | K6: =LEFT($C6,FIND("_",$C6)-1) -> C1
A7: 6 | B7: + | C7: N2_01 | D7: Get angry easily. | E7: 我容易生气。 | F7: 4 | G7: • 被打断、被否定或遇到不公平时更容易火大/烦躁 • 即使不爆发，也可能在心里生气、记很久 | H7: =IF(ISBLANK(F7),"",IF($B7="+",F7,6-F7)) -> 4 | I7: [N2] 愤怒/敌意｜神经质（Neuroticism） 定义：更容易被冒犯、挫折或不公激怒，烦躁感更强 关注：被打断/不公平；批评/否定；内心怒气与抱怨 | K7: =LEFT($C7,FIND("_",$C7)-1) -> N2
A8: 7 | B8: + | C8: E2_01 | D8: Love large parties. | E8: 我喜欢大型聚会。 | F8: 2 | G8: • 看的是对“人群/热闹场合”的偏好强度 • 关键词提示：love / large / parties | H8: =IF(ISBLANK(F8),"",IF($B8="+",F8,6-F8)) -> 2 | I8: [E2] 群居/社交性｜外向性（Extraversion） 定义：更偏好人群与热闹活动，享受社交场合 关注：喜欢聚会；结伴活动；不爱独处 | K8: =LEFT($C8,FIND("_",$C8)-1) -> E2
A9: 8 | B9: + | C9: O2_01 | D9: Believe in the importance of art. | E9: 我相信艺术的重要性。 | F9: 4 | G9: • 愿意接触艺术活动（音乐会/展览/电影/文学）并能获得愉悦 • 更在意审美与形式感（色彩、旋律、构图等） | H9: =IF(ISBLANK(F9),"",IF($B9="+",F9,6-F9)) -> 4 | I9: [O2] 艺术兴趣｜开放性（Openness） 定义：更欣赏艺术与美感，愿意接触艺术活动 关注：音乐/绘画；审美敏感；艺术体验 | K9: =LEFT($C9,FIND("_",$C9)-1) -> O2
A10: 9 | B10: + | C10: A2_01 | D10: Would never cheat on my taxes. | E10: 我永远不会作弊。 | F10: 2 | G10: • 是否会为了利益说谎/作弊/钻空子（或相反：坚持诚实） • 在没有人监督时仍会遵守原则与公平 | H10: =IF(ISBLANK(F10),"",IF($B10="+",F10,6-F10)) -> 2 | I10: [A2] 坦诚/道德｜宜人性（Agreeableness） 定义：更重视诚实与公平，较少操控或占便宜 关注：不欺骗；不钻空子；遵守原则 | K10: =LEFT($C10,FIND("_",$C10)-1) -> A2
A11: 10 | B11: + | C11: C2_02 | D11: Like order. | E11: 我喜欢秩序和条理。 | F11: 2 | G11: • 物品与信息更有条理（桌面/文件/房间常保持整洁） • 不喜欢临时找不到东西，愿意提前整理分类 | H11: =IF(ISBLANK(F11),"",IF($B11="+",F11,6-F11)) -> 2 | I11: [C2] 条理/整洁｜尽责性（Conscientiousness） 定义：更有秩序感，喜欢整理与规划 关注：收纳整洁；按流程；讨厌混乱 | K11: =LEFT($C11,FIND("_",$C11)-1) -> C2
A12: 11 | B12: + | C12: N3_01 | D12: Often feel blue. | E12: 我常常感到忧郁。 | F12: 4 | G12: • 更容易情绪低落、提不起劲（持续一段时间，而非短暂心情差） • 对原本喜欢的事也较难感到快乐或满足 | H12: =IF(ISBLANK(F12),"",IF($B12="+",F12,6-F12)) -> 4 | I12: [N3] 抑郁｜神经质（Neuroticism） 定义：更容易体验低落、无助与消极情绪 关注：情绪低落；自我否定；对生活缺乏乐趣 | K12: =LEFT($C12,FIND("_",$C12)-1) -> N3
A13: 12 | B13: + | C13: E3_01 | D13: Take charge. | E13: 我愿意承担起责任。 | F13: 4 | G13: • 更愿意带头决策、组织推进，而不是等别人安排 • 在会议/讨论中更敢表达、争取话语权 | H13: =IF(ISBLANK(F13),"",IF($B13="+",F13,6-F13)) -> 4 | I13: [E3] 自信/主导｜外向性（Extraversion） 定义：更愿意表达观点并影响他人，敢于带头 关注：发言与主张；领导/决策；不怕冲突 | K13: =LEFT($C13,FIND("_",$C13)-1) -> E3
... A69: 68 | B69: + | C69: O2_02 | D69: See beauty in things that others might not notice. | E69: 我能看到事物中别人看不到的美。 | F69: 4 | G69: • 看的是对艺术与美感的兴趣，而非专业能力 • 关键词提示：see / beauty / things | H69: =IF(ISBLANK(F69),"",IF($B69="+",F69,6-F69)) -> 4 | I69: [O2] 艺术兴趣｜开放性（Openness） 定义：更欣赏艺术与美感，愿意接触艺术活动 关注：音乐/绘画；审美敏感；艺术体验 | K69: =LEFT($C69,FIND("_",$C69)-1) -> O2
A70: 69 | B70: _ | C70: A2_07 | D70: Use flattery to get ahead. | E70: 我通过阿谀奉承来取得成功。 | F70: 2 | G70: • 看的是诚实与原则感，而非社交圆滑 • 关键词提示：use / flattery / get | H70: =IF(ISBLANK(F70),"",IF($B70="+",F70,6-F70)) -> 4 | I70: [A2] 坦诚/道德｜宜人性（Agreeableness） 定义：更重视诚实与公平，较少操控或占便宜 关注：不欺骗；不钻空子；遵守原则 | J70: ⚠️ 反向题：按题干字面作答；系统会自动翻分。若你该特质偏高，通常更倾向选“不同意/较低分”。 | K70: =LEFT($C70,FIND("_",$C70)-1) -> A2
A71: 70 | B71: + | C71: C2_03 | D71: Want everything to be "just right." | E71: 我希望一切都“恰到好处”。 | F71: 3 | G71: • 看的是秩序与整理倾向，而非审美风格 • 关键词提示：want / everything / right | H71: =IF(ISBLANK(F71),"",IF($B71="+",F71,6-F71)) -> 3 | I71: [C2] 条理/整洁｜尽责性（Conscientiousness） 定义：更有秩序感，喜欢整理与规划 关注：收纳整洁；按流程；讨厌混乱 | K71: =LEFT($C71,FIND("_",$C71)-1) -> C2
A72: 71 | B72: + | C72: N3_03 | D72: Am often down in the dumps. | E72: 我经常情绪低落。 | G72: • 更容易情绪低落、提不起劲（持续一段时间，而非短暂心情差） • 对原本喜欢的事也较难感到快乐或满足 | H72: =IF(ISBLANK(F72),"",IF($B72="+",F72,6-F72)) | I72: [N3] 抑郁｜神经质（Neuroticism） 定义：更容易体验低落、无助与消极情绪 关注：情绪低落；自我否定；对生活缺乏乐趣 | K72: =LEFT($C72,FIND("_",$C72)-1) -> N3
A73: 72 | B73: + | C73: E3_04 | D73: Can talk others into doing things. | E73: 我能说服他人，让他们做些什么。 | G73: • 看的是影响力与表达主张的倾向，不等于强势 • 关键词提示：talk / others / things | H73: =IF(ISBLANK(F73),"",IF($B73="+",F73,6-F73)) | I73: [E3] 自信/主导｜外向性（Extraversion） 定义：更愿意表达观点并影响他人，敢于带头 关注：发言与主张；领导/决策；不怕冲突 | K73: =LEFT($C73,FIND("_",$C73)-1) -> E3
A74: 73 | B74: + | C74: O3_03 | D74: Am passionate about causes. | E74: 我对事业和理想充满激情。 | G74: • 看的是情绪体验的强度与细腻程度，而非情绪好坏 • 关键词提示：passionate / causes | H74: =IF(ISBLANK(F74),"",IF($B74="+",F74,6-F74)) | I74: [O3] 情感性｜开放性（Openness） 定义：情绪体验更细腻强烈，容易被触动 关注：易感动；情绪起伏；共鸣强 | K74: =LEFT($C74,FIND("_",$C74)-1) -> O3
A75: 74 | B75: + | C75: A3_02 | D75: Love to help others. | E75: 我热爱帮助他人。 | G75: • 看到别人需要时会主动帮一把（时间/精力/资源） • 更愿意照顾他人感受并付出行动 | H75: =IF(ISBLANK(F75),"",IF($B75="+",F75,6-F75)) | I75: [A3] 利他｜宜人性（Agreeableness） 定义：更愿意帮助他人，乐于付出时间与精力 关注：主动帮忙；慷慨；愿意照顾人 | K75: =LEFT($C75,FIND("_",$C75)-1) -> A3
A76: 75 | B76: + | C76: C3_04 | D76: Pay my bills on time. | E76: 我按时付帐或还款。 | G76: • 看的是责任心与守规矩倾向 • 关键词提示：pay / bills / time | H76: =IF(ISBLANK(F76),"",IF($B76="+",F76,6-F76)) | I76: [C3] 责任感/守规｜尽责性（Conscientiousness） 定义：更遵守规则与承诺，做事可靠 关注：守时守信；履行义务；按规矩办事 | K76: =LEFT($C76,FIND("_",$C76)-1) -> C3
A77: 76 | B77: + | C77: N4_01 | D77: Find it difficult to approach others. | E77: 我觉得接近他人很困难。 | G77: • 看的是在“社会评价”情境下的紧张与退缩倾向 • 关键词提示：find / difficult / approach | H77: =IF(ISBLANK(F77),"",IF($B77="+",F77,6-F77)) | I77: [N4] 自我意识/羞怯｜神经质（Neuroticism） 定义：在他人注视或评价下更易紧张、尴尬与退缩 关注：怕出丑；怕被评判；回避成为焦点 | K77: =LEFT($C77,FIND("_",$C77)-1) -> N4
A78: 77 | B78: + | C78: E4_03 | D78: Do a lot in my spare time. | E78: 我会在空闲的时候做很多事情。 | G78: • 看的是活动水平与节奏感，而非运动能力 • 关键词提示：lot / spare / time | H78: =IF(ISBLANK(F78),"",IF($B78="+",F78,6-F78)) | I78: [E4] 活力/活动水平｜外向性（Extraversion） 定义：更忙碌有节奏，行动力与精力更高 关注：日程紧凑；坐不住；喜欢行动 | K78: =LEFT($C78,FIND("_",$C78)-1) -> E4
A79: 78 | B79: + | C79: O4_03 | D79: Am interested in many things. | E79: 我对许多事情感兴趣。 | G79: • 看的是对新奇与变化的开放程度 • 关键词提示：interested / many / things | H79: =IF(ISBLANK(F79),"",IF($B79="+",F79,6-F79)) | I79: [O4] 冒险/求新｜开放性（Openness） 定义：更愿意尝试新活动与变化，不拘泥惯例 关注：尝鲜；旅行探索；改变习惯 | K79: =LEFT($C79,FIND("_",$C79)-1) -> O4
A80: 79 | B80: + | C80: A4_03 | D80: Hate to seem pushy. | E80: 我讨厌被认为是咄咄逼人的。 | G80: • 看的是在冲突/谈判中的合作 vs 对抗取向 • 关键词提示：hate / seem / pushy | H80: =IF(ISBLANK(F80),"",IF($B80="+",F80,6-F80)) | I80: [A4] 合作｜宜人性（Agreeableness） 定义：更愿意妥协与和解，减少对抗 关注：避免争吵；愿意让步；顾全大局 | K80: =LEFT($C80,FIND("_",$C80)-1) -> A4
A81: 80 | B81: + | C81: C4_04 | D81: Turn plans into actions. | E81: 我会把计划变成行动。 | G81: • 看的是上进心与目标驱动，而非是否焦虑 • 关键词提示：turn / plans / actions | H81: =IF(ISBLANK(F81),"",IF($B81="+",F81,6-F81)) | I81: [C4] 成就追求｜尽责性（Conscientiousness） 定义：更有目标与上进心，愿意努力提高 关注：设目标；努力拼；追求更好 | K81: =LEFT($C81,FIND("_",$C81)-1) -> C4
A82: 81 | B82: + | C82: N5_04 | D82: Do things I later regret. | E82: 我会做一些自己后来感到后悔的事情。 | G82: • 关注“克制力/延迟满足”能力，而非道德评价 • 关键词提示：things / later / regret | H82: =IF(ISBLANK(F82),"",IF($B82="+",F82,6-F82)) | I82: [N5] 冲动性/放纵｜神经质（Neuroticism） 定义：更难抵御诱惑，容易情绪化满足欲望 关注：食物/消费/娱乐；难以克制；事后后悔 | K82: =LEFT($C82,FIND("_",$C82)-1) -> N5
A83: 82 | B83: + | C83: E5_05 | D83: Love action. | E83: 我喜欢行动起来。 | G83: • 看的是对刺激/风险的偏好，不等于鲁莽 • 关键词提示：love / action | H83: =IF(ISBLANK(F83),"",IF($B83="+",F83,6-F83)) | I83: [E5] 刺激寻求｜外向性（Extraversion） 定义：更追求新奇与刺激，不太怕风险 关注：冒险体验；寻求兴奋；不喜单调 | K83: =LEFT($C83,FIND("_",$C83)-1) -> E5
... A99: 98 | B99: + | C99: O2_04 | D99: Love flowers. | E99: 我喜欢花。 | G99: • 看的是对艺术与美感的兴趣，而非专业能力 • 关键词提示：love / flowers | H99: =IF(ISBLANK(F99),"",IF($B99="+",F99,6-F99)) | I99: [O2] 艺术兴趣｜开放性（Openness） 定义：更欣赏艺术与美感，愿意接触艺术活动 关注：音乐/绘画；审美敏感；艺术体验 | K99: =LEFT($C99,FIND("_",$C99)-1) -> O2
A100: 99 | B100: _ | C100: A2_03 | D100: Use others for my own ends. | E100: 我会利用他人达到自己的目的。 | G100: • 看的是诚实与原则感，而非社交圆滑 • 关键词提示：use / others / ends | H100: =IF(ISBLANK(F100),"",IF($B100="+",F100,6-F100)) | I100: [A2] 坦诚/道德｜宜人性（Agreeableness） 定义：更重视诚实与公平，较少操控或占便宜 关注：不欺骗；不钻空子；遵守原则 | J100: ⚠️ 反向题：按题干字面作答；系统会自动翻分。若你该特质偏高，通常更倾向选“不同意/较低分”。 | K100: =LEFT($C100,FIND("_",$C100)-1) -> A2
A101: 100 | B101: + | C101: C2_04 | D101: Love order and regularity. | E101: 我喜欢条理和规律。 | G101: • 物品与信息更有条理（桌面/文件/房间常保持整洁） • 不喜欢临时找不到东西，愿意提前整理分类 | H101: =IF(ISBLANK(F101),"",IF($B101="+",F101,6-F101)) | I101: [C2] 条理/整洁｜尽责性（Conscientiousness） 定义：更有秩序感，喜欢整理与规划 关注：收纳整洁；按流程；讨厌混乱 | K101: =LEFT($C101,FIND("_",$C101)-1) -> C2
A102: 101 | B102: + | C102: N3_04 | D102: Have a low opinion of myself. | E102: 我对自己的评价很低。 | G102: • 关注长期的低落/无助感倾向，而不是一天的情绪波动 • 关键词提示：low / opinion | H102: =IF(ISBLANK(F102),"",IF($B102="+",F102,6-F102)) | I102: [N3] 抑郁｜神经质（Neuroticism） 定义：更容易体验低落、无助与消极情绪 关注：情绪低落；自我否定；对生活缺乏乐趣 | K102: =LEFT($C102,FIND("_",$C102)-1) -> N3
A103: 102 | B103: + | C103: E3_05 | D103: Seek to influence others. | E103: 我寻求对他人产生影响。 | G103: • 看的是影响力与表达主张的倾向，不等于强势 • 关键词提示：seek / influence / others | H103: =IF(ISBLANK(F103),"",IF($B103="+",F103,6-F103)) | I103: [E3] 自信/主导｜外向性（Extraversion） 定义：更愿意表达观点并影响他人，敢于带头 关注：发言与主张；领导/决策；不怕冲突 | K103: =LEFT($C103,FIND("_",$C103)-1) -> E3
A104: 103 | B104: + | C104: O3_04 | D104: Enjoy examining myself and my life. | E104: 我喜欢审视自己和生活。 | G104: • 看的是情绪体验的强度与细腻程度，而非情绪好坏 • 关键词提示：enjoy / examining / life | H104: =IF(ISBLANK(F104),"",IF($B104="+",F104,6-F104)) | I104: [O3] 情感性｜开放性（Openness） 定义：情绪体验更细腻强烈，容易被触动 关注：易感动；情绪起伏；共鸣强 | K104: =LEFT($C104,FIND("_",$C104)-1) -> O3
A105: 104 | B105: + | C105: A3_01 | D105: Am concerned about others. | E105: 我会关心、挂念他人。 | G105: • 看的是愿意为他人付出的倾向，而不是礼貌程度 • 关键词提示：concerned / others | H105: =IF(ISBLANK(F105),"",IF($B105="+",F105,6-F105)) | I105: [A3] 利他｜宜人性（Agreeableness） 定义：更愿意帮助他人，乐于付出时间与精力 关注：主动帮忙；慷慨；愿意照顾人 | K105: =LEFT($C105,FIND("_",$C105)-1) -> A3
A106: 105 | B106: + | C106: C3_02 | D106: Tell the truth. | E106: 我总是说真话。 | G106: • 看的是责任心与守规矩倾向 • 关键词提示：tell / truth | H106: =IF(ISBLANK(F106),"",IF($B106="+",F106,6-F106)) | I106: [C3] 责任感/守规｜尽责性（Conscientiousness） 定义：更遵守规则与承诺，做事可靠 关注：守时守信；履行义务；按规矩办事 | K106: =LEFT($C106,FIND("_",$C106)-1) -> C3
A107: 106 | B107: + | C107: N4_02 | D107: Am afraid to draw attention to myself. | E107: 我害怕引起别人对自己的注意。 | G107: • 看的是在“社会评价”情境下的紧张与退缩倾向 • 关键词提示：afraid / draw / attention | H107: =IF(ISBLANK(F107),"",IF($B107="+",F107,6-F107)) | I107: [N4] 自我意识/羞怯｜神经质（Neuroticism） 定义：在他人注视或评价下更易紧张、尴尬与退缩 关注：怕出丑；怕被评判；回避成为焦点 | K107: =LEFT($C107,FIND("_",$C107)-1) -> N4
A108: 107 | B108: + | C108: E4_04 | D108: Can manage many things at the same time. | E108: 我能同时处理许多事情。 | G108: • 看的是活动水平与节奏感，而非运动能力 • 关键词提示：manage / many / things | H108: =IF(ISBLANK(F108),"",IF($B108="+",F108,6-F108)) | I108: [E4] 活力/活动水平｜外向性（Extraversion） 定义：更忙碌有节奏，行动力与精力更高 关注：日程紧凑；坐不住；喜欢行动 | K108: =LEFT($C108,FIND("_",$C108)-1) -> E4
A109: 108 | B109: + | C109: O4_04 | D109: Like to begin new things. | E109: 我喜欢做没做过的事情。 | G109: • 看的是对新奇与变化的开放程度 • 关键词提示：like / begin / new | H109: =IF(ISBLANK(F109),"",IF($B109="+",F109,6-F109)) | I109: [O4] 冒险/求新｜开放性（Openness） 定义：更愿意尝试新活动与变化，不拘泥惯例 关注：尝鲜；旅行探索；改变习惯 | K109: =LEFT($C109,FIND("_",$C109)-1) -> O4
A110: 109 | B110: _ | C110: A4_08 | D110: Have a sharp tongue. | E110: 我说话是尖锐的。 | G110: • 看的是在冲突/谈判中的合作 vs 对抗取向 • 关键词提示：sharp / tongue | H110: =IF(ISBLANK(F110),"",IF($B110="+",F110,6-F110)) | I110: [A4] 合作｜宜人性（Agreeableness） 定义：更愿意妥协与和解，减少对抗 关注：避免争吵；愿意让步；顾全大局 | J110: ⚠️ 反向题：按题干字面作答；系统会自动翻分。若你该特质偏高，通常更倾向选“不同意/较低分”。 | K110: =LEFT($C110,FIND("_",$C110)-1) -> A4
...

Sheet Scoring
A1: 自动算分 / Scoring
A2: 说明：在“Test_Sorted”工作表的 F 列填写 1-5 分（1=非常不符合 … 5=非常符合），系统会自动反向计分并汇总。
A4: Facet（分面） | B4: Average（平均分） | C4: Sum（总分） | D4: Answered（已答题数）
A5: A1 | B5: =IF($D5=0,"",$C5/$D5) -> 1.8333333 | C5: =IF($D5=0,"",SUMIFS(Test_Sorted!$H$2:$H$301,Test_Sorted!$K$2:$K$301,$A5)) -> 5.5 | D5: =COUNTIFS(Test_Sorted!$K$2:$K$301,$A5,Test_Sorted!$H$2:$H$301,">0") -> 3
A6: A2 | B6: =IF($D6=0,"",$C6/$D6) -> 2.5 | C6: =IF($D6=0,"",SUMIFS(Test_Sorted!$H$2:$H$301,Test_Sorted!$K$2:$K$301,$A6)) -> 7.5 | D6: =COUNTIFS(Test_Sorted!$K$2:$K$301,$A6,Test_Sorted!$H$2:$H$301,">0") -> 3
A7: A3 | B7: =IF($D7=0,"",$C7/$D7) -> 3.625 | C7: =IF($D7=0,"",SUMIFS(Test_Sorted!$H$2:$H$301,Test_Sorted!$K$2:$K$301,$A7)) -> 7.25 | D7: =COUNTIFS(Test_Sorted!$K$2:$K$301,$A7,Test_Sorted!$H$2:$H$301,">0") -> 2
A8: A4 | B8: =IF($D8=0,"",$C8/$D8) -> 1.75 | C8: =IF($D8=0,"",SUMIFS(Test_Sorted!$H$2:$H$301,Test_Sorted!$K$2:$K$301,$A8)) -> 3.5 | D8: =COUNTIFS(Test_Sorted!$K$2:$K$301,$A8,Test_Sorted!$H$2:$H$301,">0") -> 2
A9: A5 | B9: =IF($D9=0,"",$C9/$D9) -> 4 | C9: =IF($D9=0,"",SUMIFS(Test_Sorted!$H$2:$H$301,Test_Sorted!$K$2:$K$301,$A9)) -> 8 | D9: =COUNTIFS(Test_Sorted!$K$2:$K$301,$A9,Test_Sorted!$H$2:$H$301,">0") -> 2
A10: A6 | B10: =IF($D10=0,"",$C10/$D10) -> 2.875 | C10: =IF($D10=0,"",SUMIFS(Test_Sorted!$H$2:$H$301,Test_Sorted!$K$2:$K$301,$A10)) -> 5.75 | D10: =COUNTIFS(Test_Sorted!$K$2:$K$301,$A10,Test_Sorted!$H$2:$H$301,">0") -> 2
A11: C1 | B11: =IF($D11=0,"",$C11/$D11) -> 4.1666667 | C11: =IF($D11=0,"",SUMIFS(Test_Sorted!$H$2:$H$301,Test_Sorted!$K$2:$K$301,$A11)) -> 12.5 | D11: =COUNTIFS(Test_Sorted!$K$2:$K$301,$A11,Test_Sorted!$H$2:$H$301,">0") -> 3
A12: C2 | B12: =IF($D12=0,"",$C12/$D12) -> 2 | C12: =IF($D12=0,"",SUMIFS(Test_Sorted!$H$2:$H$301,Test_Sorted!$K$2:$K$301,$A12)) -> 6 | D12: =COUNTIFS(Test_Sorted!$K$2:$K$301,$A12,Test_Sorted!$H$2:$H$301,">0") -> 3
A13: C3 | B13: =IF($D13=0,"",$C13/$D13) -> 2 | C13: =IF($D13=0,"",SUMIFS(Test_Sorted!$H$2:$H$301,Test_Sorted!$K$2:$K$301,$A13)) -> 4 | D13: =COUNTIFS(Test_Sorted!$K$2:$K$301,$A13,Test_Sorted!$H$2:$H$301,">0") -> 2
A14: C4 | B14: =IF($D14=0,"",$C14/$D14) -> 4.5 | C14: =IF($D14=0,"",SUMIFS(Test_Sorted!$H$2:$H$301,Test_Sorted!$K$2:$K$301,$A14)) -> 9 | D14: =COUNTIFS(Test_Sorted!$K$2:$K$301,$A14,Test_Sorted!$H$2:$H$301,">0") -> 2
A15: C5 | B15: =IF($D15=0,"",$C15/$D15) -> 1.75 | C15: =IF($D15=0,"",SUMIFS(Test_Sorted!$H$2:$H$301,Test_Sorted!$K$2:$K$301,$A15)) -> 3.5 | D15: =COUNTIFS(Test_Sorted!$K$2:$K$301,$A15,Test_Sorted!$H$2:$H$301,">0") -> 2
A16: C6 | B16: =IF($D16=0,"",$C16/$D16) -> 4.5 | C16: =IF($D16=0,"",SUMIFS(Test_Sorted!$H$2:$H$301,Test_Sorted!$K$2:$K$301,$A16)) -> 9 | D16: =COUNTIFS(Test_Sorted!$K$2:$K$301,$A16,Test_Sorted!$H$2:$H$301,">0") -> 2
... A34: O6 | B34: =IF($D34=0,"",$C34/$D34) -> 4.25 | C34: =IF($D34=0,"",SUMIFS(Test_Sorted!$H$2:$H$301,Test_Sorted!$K$2:$K$301,$A34)) -> 8.5 | D34: =COUNTIFS(Test_Sorted!$K$2:$K$301,$A34,Test_Sorted!$H$2:$H$301,">0") -> 2
A37: Domains（维度）
A38: Domain | B38: Average（平均分） | C38: Sum（总分） | D38: Answered（已答题数）
A39: A (Agreeableness) | B39: =IF($D39=0,"",$C39/$D39) -> 2.6785714 | C39: =IF($D39=0,"",SUMIF(Test_Sorted!$C$2:$C$301,"A*",Test_Sorted!$H$2:$H$301)) -> 37.5 | D39: =COUNTIFS(Test_Sorted!$C$2:$C$301,"A*",Test_Sorted!$H$2:$H$301,">0") -> 14
A40: C (Conscientiousness) | B40: =IF($D40=0,"",$C40/$D40) -> 3.1428571 | C40: =IF($D40=0,"",SUMIF(Test_Sorted!$C$2:$C$301,"C*",Test_Sorted!$H$2:$H$301)) -> 44 | D40: =COUNTIFS(Test_Sorted!$C$2:$C$301,"C*",Test_Sorted!$H$2:$H$301,">0") -> 14
A41: E (Extraversion) | B41: =IF($D41=0,"",$C41/$D41) -> 3.2142857 | C41: =IF($D41=0,"",SUMIF(Test_Sorted!$C$2:$C$301,"E*",Test_Sorted!$H$2:$H$301)) -> 45 | D41: =COUNTIFS(Test_Sorted!$C$2:$C$301,"E*",Test_Sorted!$H$2:$H$301,">0") -> 14
A42: N (Neuroticism) | B42: =IF($D42=0,"",$C42/$D42) -> 3.875 | C42: =IF($D42=0,"",SUMIF(Test_Sorted!$C$2:$C$301,"N*",Test_Sorted!$H$2:$H$301)) -> 54.25 | D42: =COUNTIFS(Test_Sorted!$C$2:$C$301,"N*",Test_Sorted!$H$2:$H$301,">0") -> 14
A43: O (Openness) | B43: =IF($D43=0,"",$C43/$D43) -> 4.0714286 | C43: =IF($D43=0,"",SUMIF(Test_Sorted!$C$2:$C$301,"O*",Test_Sorted!$H$2:$H$301)) -> 57 | D43: =COUNTIFS(Test_Sorted!$C$2:$C$301,"O*",Test_Sorted!$H$2:$H$301,">0") -> 14
A45: Total (All 300) | B45: =IF($D45=0,"",$C45/$D45) -> 3.3964286 | C45: =IF($D45=0,"",SUM(Test_Sorted!$H$2:$H$301)) -> 237.75 | D45: =COUNTIFS(Test_Sorted!$H$2:$H$301,">0") -> 70
A47: 提示：以上为原始平均分（1-5）。如需转换为标准分/百分位，需要常模数据。

Sheet Translation_Revision_Log
A1: Number | B1: English Item | C1: Original Chinese | D1: Revised Chinese | E1: Changed?
A2: 4 | B2: Trust others. | C2: 我信任他人。 | D2: 我信任他人。
A3: 34 | B3: Believe that others have good intentions. | C3: 我相信他人是心怀好意的。 | D3: 我相信他人是心怀好意的。
A4: 64 | B4: Trust what people say. | C4: 我信任別人说的话。 | D4: 我信任别人说的话。 | E4: Y
A5: 94 | B5: Believe that people are basically moral. | C5: 我相信人从根本上来说都是遵守道德的。 | D5: 我相信人从根本上来说都是遵守道德的。
A6: 124 | B6: Believe in human goodness. | C6: 我相信人类是善良的。 | D6: 我相信人类是善良的。
A7: 154 | B7: Think that all will be well. | C7: 我认为一切事情都会变好。 | D7: 我认为一切事情都会变好。
A8: 184 | B8: Distrust people. | C8: 我不信任他人。 | D8: 我不信任他人。
A9: 214 | B9: Suspect hidden motives in others. | C9: 我怀疑他人另有所谋。 | D9: 我怀疑他人另有所谋。
A10: 244 | B10: Am wary of others. | C10: 我对他人心存戒备。 | D10: 我对他人心存戒备。
A11: 274 | B11: Believe that people are essentially evil. | C11: 我相信人本质上是邪恶的。 | D11: 我相信人本质上是邪恶的。
A12: 9 | B12: Would never cheat on my taxes. | C12: 我永远不会作弊。 | D12: 我永远不会作弊。
A13: 39 | B13: Stick to the rules. | C13: 我谨守规则。 | D13: 我谨守规则。
A14: 99 | B14: Use others for my own ends. | C14: 我会利用他人达到自己的目的。 | D14: 我会利用他人达到自己的目的。
A15: 159 | B15: Cheat to get ahead. | C15: 我通过欺骗的方式来换取成功。 | D15: 我通过欺骗的方式来换取成功。
A16: 249 | B16: Take advantage of others. | C16: 我会利用他人。 | D16: 我会利用他人。
... A32: 19 | B32: Am easy to satisfy. | C32: 我容易感到满意。 | D32: 我容易感到满意。
A33: 49 | B33: Can't stand confrontations. | C33: 冲突和对抗使我无法忍受。 | D33: 我无法忍受冲突和对抗。 | E33: Y
A34: 79 | B34: Hate to seem pushy. | C34: 我讨厌被认为是咄咄逼人的。 | D34: 我讨厌被认为是咄咄逼人的。
A35: 169 | B35: Love a good fight. | C35: 我会喜欢一场精彩的争斗。 | D35: 我会喜欢一场精彩的争斗。
A36: 199 | B36: Yell at people. | C36: 我常对人大喊大叫。 | D36: 我常对人大喊大叫。
A37: 229 | B37: Insult people. | C37: 我会侮辱别人。 | D37: 我会侮辱别人。
A38: 259 | B38: Get back at others. | C38: 我会报复他人。 | D38: 我会报复他人。
A39: 109 | B39: Have a sharp tongue. | C39: 我说话是尖锐的。 | D39: 我说话是尖锐的。
A40: 139 | B40: Contradict others. | C40: 我常常反驳他人。 | D40: 我常常反驳他人。
A41: 289 | B41: Hold a grudge. | C41: 我总是心怀怨恨。 | D41: 我总是心怀怨恨。
A42: 24 | B42: Dislike being the center of attention. | C42: 我不喜欢成为关注的焦点。 | D42: 我不喜欢成为关注的焦点。
A43: 54 | B43: Dislike talking about myself. | C43: 我不喜欢谈论自己 | D43: 我不喜欢谈论自己。 | E43: Y
A44: 84 | B44: Consider myself an average person. | C44: 我认为自己是一个非常普通的人。 | D44: 我认为自己是一个非常普通的人。
A45: 114 | B45: Seldom toot my own horn. | C45: 我很少炫耀自己的成就。 | D45: 我很少炫耀自己的成就。
A46: 144 | B46: Believe that I am better than others. | C46: 我相信自己要比别人出色。 | D46: 我相信自己要比别人出色。
A47: 174 | B47: Think highly of myself. | C47: 我对自己的评价很高。 | D47: 我对自己的评价很高。
A48: 204 | B48: Have a high opinion of myself. | C48: 我对自己有很高的评价。 | D48: 我对自己有很高的评价。
A49: 264 | B49: Boast about my virtues. | C49: 我会夸耀自己的长处。 | D49: 我会夸耀自己的长处。
A50: 234 | B50: Know the answers to many questions. | C50: 我知道许多事情的解决方法和答案。 | D50: 我知道许多事情的解决方法和答案。
A51: 294 | B51: Make myself the center of attention. | C51: 我会让自己成为注意的焦点。 | D51: 我会让自己成为注意的焦点。
A52: 29 | B52: Sympathize with the homeless. | C52: 我同情无家可归的人。 | D52: 我同情无家可归的人。
A53: 59 | B53: Feel sympathy for those who are worse off than myself. | C53: 我对处境比自己糟糕的人感到同情。 | D53: 我对处境比自己糟糕的人感到同情。
A54: 89 | B54: Value cooperation over competition. | C54: 相比竞争，我更珍视合作。 | D54: 我更看重合作而不是竞争。 | E54: Y
A55: 119 | B55: Suffer from others' sorrows. | C55: 我能从别人的痛苦中感受到痛苦。 | D55: 我能从别人的痛苦中感受到痛苦。
...

Sheet Context_Backup
A1: Number | B1: Old Context / 旧注释（备份）
A2: 1 | B2: 分面：N1 焦虑（神经质 N） 作答时请结合过去6–12个月的“常态”，重点考虑： • 社交/评价：担心出错、被否定、在众人面前表现不好 • 安全/健康：对疾病、意外、风险有较强的危机感或担忧 • 不确定性：对变化、未知、等待结果更容易紧张/坐立不安
A3: 2 | B3: 分面：E1 热情/亲和（外向 E） 作答时请结合过去6–12个月的“常态”，重点考虑： • 亲近与友善：更愿意表达关心、赞美、温暖 • 建立关系：更容易与人熟络、拉近距离 • 回应性：别人示好时更愿意回应与互动
A4: 3 | B4: 分面：O1 幻想/想象（开放 O） 作答时请结合过去6–12个月的“常态”，重点考虑： • 想象世界：更常白日梦、构思故事/情节/画面 • 心理模拟：遇事会在脑中预演、创造多种可能 • 沉浸体验：容易被文学/影视/游戏的情境带入
A5: 4 | B5: 分面：A1 信任（宜人性 A） 作答时请结合过去6–12个月的“常态”，重点考虑： • 善意假设：更倾向相信别人动机是好的 • 低戒心：不太疑神疑鬼，较少怀疑他人欺骗 • 合作期待：更愿意给别人机会、先信后证
A6: 5 | B6: 分面：C1 胜任感（尽责性 C） 作答时请结合过去6–12个月的“常态”，重点考虑： • 自我效能：相信自己能把事情处理好 • 问题解决：遇到任务会想办法而不是退缩 • 可靠程度：别人交代的事你更能完成到位
A7: 6 | B7: 分面：N2 愤怒/敌意（神经质 N） 作答时请结合过去6–12个月的“常态”，重点考虑： • 易被冒犯：对不公平/不尊重更敏感，容易“火大” • 怨怼与挑剔：更常记仇、抱怨、挑人毛病 • 对抗反应：更可能顶嘴、争辩、用讽刺/冷淡表达不满
A8: 7 | B8: 分面：E2 群居/合群（外向 E） 作答时请结合过去6–12个月的“常态”，重点考虑： • 偏好人群：更喜欢与多人一起活动而非独处 • 社交能量：社交后更充电而非被耗尽 • 主动参与：更愿意加入聚会、团体与社交场景
A9: 8 | B9: 分面：O2 审美（开放 O） 作答时请结合过去6–12个月的“常态”，重点考虑： • 美感敏感：更容易被音乐、绘画、设计、自然之美打动 • 主动接触：更愿意看展、听音乐、关注审美细节 • 品味追求：对风格、质感、配色等更在意
A10: 9 | B10: 分面：A2 坦诚（宜人性 A） 作答时请结合过去6–12个月的“常态”，重点考虑： • 真诚直率：更少耍心机、话里有话或操控 • 公平交换：不太占便宜，愿意按规则来 • 言行一致：说到做到，不用虚假包装自己
A11: 10 | B11: 分面：C2 条理（尽责性 C） 作答时请结合过去6–12个月的“常态”，重点考虑： • 整洁有序：物品、时间、信息更倾向被整理 • 偏好规划：喜欢清单、规则、步骤与结构 • 厌恶混乱：环境/流程乱会让你不舒服
A12: 11 | B12: 分面：N3 抑郁（神经质 N） 作答时请结合过去6–12个月的“常态”，重点考虑： • 情绪低落：更常感到沮丧、无力、心情沉重 • 消极认知：更容易自责、悲观、觉得事情没希望 • 快感降低：对原本喜欢的事更难感到开心或投入
A13: 12 | B13: 分面：E3 果断/支配（外向 E） 作答时请结合过去6–12个月的“常态”，重点考虑： • 带头与影响：更愿意主导、组织、推动进度 • 表达立场：更敢说出不同意见、为自己争取 • 社交主动：在人群中更愿意发言与掌控话题
... A301: 300 | B301: 分面：C6 审慎（尽责性 C） 作答时请结合过去6–12个月的“常态”，重点考虑： • 三思而后行：做决定前会权衡后果与风险 • 冲动抑制：较少因一时情绪就拍板 • 计划性：更愿意先想清楚步骤再行动 注意：本题为反向表述（文字是相反说法），仍请按你真实倾向作答。
